2016-06-29 14:40:19,812 [Thread-2:111128] [django.request:256] [ERROR]- Internal Server Error: /admin/bbs/bbs/
Traceback (most recent call last):
  File "D:\Python27\lib\site-packages\django\core\handlers\base.py", line 119, in get_response
    resolver_match = resolver.resolve(request.path_info)
  File "D:\Python27\lib\site-packages\django\core\urlresolvers.py", line 366, in resolve
    for pattern in self.url_patterns:
  File "D:\Python27\lib\site-packages\django\core\urlresolvers.py", line 402, in url_patterns
    patterns = getattr(self.urlconf_module, "urlpatterns", self.urlconf_module)
  File "D:\Python27\lib\site-packages\django\core\urlresolvers.py", line 396, in urlconf_module
    self._urlconf_module = import_module(self.urlconf_name)
  File "D:\Python27\lib\importlib\__init__.py", line 37, in import_module
    __import__(name)
  File "H:\Coding\workstation\BBS_Pro\src\BBS_Pro\urls.py", line 54, in <module>
    url(r'^ckeditor/', include('ckeditor.urls')),
  File "D:\Python27\lib\site-packages\django\conf\urls\__init__.py", line 33, in include
    urlconf_module = import_module(urlconf_module)
  File "D:\Python27\lib\importlib\__init__.py", line 37, in import_module
    __import__(name)
ImportError: No module named urls
2016-06-29 14:40:28,907 [Thread-3:111152] [django.request:256] [ERROR]- Internal Server Error: /
Traceback (most recent call last):
  File "D:\Python27\lib\site-packages\django\core\handlers\base.py", line 119, in get_response
    resolver_match = resolver.resolve(request.path_info)
  File "D:\Python27\lib\site-packages\django\core\urlresolvers.py", line 366, in resolve
    for pattern in self.url_patterns:
  File "D:\Python27\lib\site-packages\django\core\urlresolvers.py", line 402, in url_patterns
    patterns = getattr(self.urlconf_module, "urlpatterns", self.urlconf_module)
  File "D:\Python27\lib\site-packages\django\core\urlresolvers.py", line 396, in urlconf_module
    self._urlconf_module = import_module(self.urlconf_name)
  File "D:\Python27\lib\importlib\__init__.py", line 37, in import_module
    __import__(name)
  File "H:\Coding\workstation\BBS_Pro\src\BBS_Pro\urls.py", line 54, in <module>
    url(r'^ckeditor/', include('ckeditor.urls')),
  File "D:\Python27\lib\site-packages\django\conf\urls\__init__.py", line 33, in include
    urlconf_module = import_module(urlconf_module)
  File "D:\Python27\lib\importlib\__init__.py", line 37, in import_module
    __import__(name)
ImportError: No module named urls
2016-06-29 14:42:02,283 [Thread-4:111456] [django.request:256] [ERROR]- Internal Server Error: /
Traceback (most recent call last):
  File "D:\Python27\lib\site-packages\django\core\handlers\base.py", line 119, in get_response
    resolver_match = resolver.resolve(request.path_info)
  File "D:\Python27\lib\site-packages\django\core\urlresolvers.py", line 366, in resolve
    for pattern in self.url_patterns:
  File "D:\Python27\lib\site-packages\django\core\urlresolvers.py", line 402, in url_patterns
    patterns = getattr(self.urlconf_module, "urlpatterns", self.urlconf_module)
  File "D:\Python27\lib\site-packages\django\core\urlresolvers.py", line 396, in urlconf_module
    self._urlconf_module = import_module(self.urlconf_name)
  File "D:\Python27\lib\importlib\__init__.py", line 37, in import_module
    __import__(name)
  File "H:\Coding\workstation\BBS_Pro\src\BBS_Pro\urls.py", line 54, in <module>
    url(r'^ckeditor/', include('ckeditor.urls')),
  File "D:\Python27\lib\site-packages\django\conf\urls\__init__.py", line 33, in include
    urlconf_module = import_module(urlconf_module)
  File "D:\Python27\lib\importlib\__init__.py", line 37, in import_module
    __import__(name)
ImportError: No module named urls
2016-06-29 14:42:05,545 [Thread-5:111484] [django.request:256] [ERROR]- Internal Server Error: /
Traceback (most recent call last):
  File "D:\Python27\lib\site-packages\django\core\handlers\base.py", line 119, in get_response
    resolver_match = resolver.resolve(request.path_info)
  File "D:\Python27\lib\site-packages\django\core\urlresolvers.py", line 366, in resolve
    for pattern in self.url_patterns:
  File "D:\Python27\lib\site-packages\django\core\urlresolvers.py", line 402, in url_patterns
    patterns = getattr(self.urlconf_module, "urlpatterns", self.urlconf_module)
  File "D:\Python27\lib\site-packages\django\core\urlresolvers.py", line 396, in urlconf_module
    self._urlconf_module = import_module(self.urlconf_name)
  File "D:\Python27\lib\importlib\__init__.py", line 37, in import_module
    __import__(name)
  File "H:\Coding\workstation\BBS_Pro\src\BBS_Pro\urls.py", line 54, in <module>
    url(r'^ckeditor/', include('ckeditor.urls')),
  File "D:\Python27\lib\site-packages\django\conf\urls\__init__.py", line 33, in include
    urlconf_module = import_module(urlconf_module)
  File "D:\Python27\lib\importlib\__init__.py", line 37, in import_module
    __import__(name)
ImportError: No module named urls
2016-06-29 14:42:07,480 [Thread-6:111488] [django.request:256] [ERROR]- Internal Server Error: /
Traceback (most recent call last):
  File "D:\Python27\lib\site-packages\django\core\handlers\base.py", line 119, in get_response
    resolver_match = resolver.resolve(request.path_info)
  File "D:\Python27\lib\site-packages\django\core\urlresolvers.py", line 366, in resolve
    for pattern in self.url_patterns:
  File "D:\Python27\lib\site-packages\django\core\urlresolvers.py", line 402, in url_patterns
    patterns = getattr(self.urlconf_module, "urlpatterns", self.urlconf_module)
  File "D:\Python27\lib\site-packages\django\core\urlresolvers.py", line 396, in urlconf_module
    self._urlconf_module = import_module(self.urlconf_name)
  File "D:\Python27\lib\importlib\__init__.py", line 37, in import_module
    __import__(name)
  File "H:\Coding\workstation\BBS_Pro\src\BBS_Pro\urls.py", line 54, in <module>
    url(r'^ckeditor/', include('ckeditor.urls')),
  File "D:\Python27\lib\site-packages\django\conf\urls\__init__.py", line 33, in include
    urlconf_module = import_module(urlconf_module)
  File "D:\Python27\lib\importlib\__init__.py", line 37, in import_module
    __import__(name)
ImportError: No module named urls
2016-06-29 14:42:08,398 [Thread-7:111496] [django.request:256] [ERROR]- Internal Server Error: /
Traceback (most recent call last):
  File "D:\Python27\lib\site-packages\django\core\handlers\base.py", line 119, in get_response
    resolver_match = resolver.resolve(request.path_info)
  File "D:\Python27\lib\site-packages\django\core\urlresolvers.py", line 366, in resolve
    for pattern in self.url_patterns:
  File "D:\Python27\lib\site-packages\django\core\urlresolvers.py", line 402, in url_patterns
    patterns = getattr(self.urlconf_module, "urlpatterns", self.urlconf_module)
  File "D:\Python27\lib\site-packages\django\core\urlresolvers.py", line 396, in urlconf_module
    self._urlconf_module = import_module(self.urlconf_name)
  File "D:\Python27\lib\importlib\__init__.py", line 37, in import_module
    __import__(name)
  File "H:\Coding\workstation\BBS_Pro\src\BBS_Pro\urls.py", line 54, in <module>
    url(r'^ckeditor/', include('ckeditor.urls')),
  File "D:\Python27\lib\site-packages\django\conf\urls\__init__.py", line 33, in include
    urlconf_module = import_module(urlconf_module)
  File "D:\Python27\lib\importlib\__init__.py", line 37, in import_module
    __import__(name)
ImportError: No module named urls
2016-06-29 14:42:09,289 [Thread-8:111500] [django.request:256] [ERROR]- Internal Server Error: /
Traceback (most recent call last):
  File "D:\Python27\lib\site-packages\django\core\handlers\base.py", line 119, in get_response
    resolver_match = resolver.resolve(request.path_info)
  File "D:\Python27\lib\site-packages\django\core\urlresolvers.py", line 366, in resolve
    for pattern in self.url_patterns:
  File "D:\Python27\lib\site-packages\django\core\urlresolvers.py", line 402, in url_patterns
    patterns = getattr(self.urlconf_module, "urlpatterns", self.urlconf_module)
  File "D:\Python27\lib\site-packages\django\core\urlresolvers.py", line 396, in urlconf_module
    self._urlconf_module = import_module(self.urlconf_name)
  File "D:\Python27\lib\importlib\__init__.py", line 37, in import_module
    __import__(name)
  File "H:\Coding\workstation\BBS_Pro\src\BBS_Pro\urls.py", line 54, in <module>
    url(r'^ckeditor/', include('ckeditor.urls')),
  File "D:\Python27\lib\site-packages\django\conf\urls\__init__.py", line 33, in include
    urlconf_module = import_module(urlconf_module)
  File "D:\Python27\lib\importlib\__init__.py", line 37, in import_module
    __import__(name)
ImportError: No module named urls
2016-06-29 14:42:09,387 [Thread-9:111504] [django.request:256] [ERROR]- Internal Server Error: /
Traceback (most recent call last):
  File "D:\Python27\lib\site-packages\django\core\handlers\base.py", line 119, in get_response
    resolver_match = resolver.resolve(request.path_info)
  File "D:\Python27\lib\site-packages\django\core\urlresolvers.py", line 366, in resolve
    for pattern in self.url_patterns:
  File "D:\Python27\lib\site-packages\django\core\urlresolvers.py", line 402, in url_patterns
    patterns = getattr(self.urlconf_module, "urlpatterns", self.urlconf_module)
  File "D:\Python27\lib\site-packages\django\core\urlresolvers.py", line 396, in urlconf_module
    self._urlconf_module = import_module(self.urlconf_name)
  File "D:\Python27\lib\importlib\__init__.py", line 37, in import_module
    __import__(name)
  File "H:\Coding\workstation\BBS_Pro\src\BBS_Pro\urls.py", line 54, in <module>
    url(r'^ckeditor/', include('ckeditor.urls')),
  File "D:\Python27\lib\site-packages\django\conf\urls\__init__.py", line 33, in include
    urlconf_module = import_module(urlconf_module)
  File "D:\Python27\lib\importlib\__init__.py", line 37, in import_module
    __import__(name)
ImportError: No module named urls
2016-06-29 14:42:09,548 [Thread-10:111508] [django.request:256] [ERROR]- Internal Server Error: /
Traceback (most recent call last):
  File "D:\Python27\lib\site-packages\django\core\handlers\base.py", line 119, in get_response
    resolver_match = resolver.resolve(request.path_info)
  File "D:\Python27\lib\site-packages\django\core\urlresolvers.py", line 366, in resolve
    for pattern in self.url_patterns:
  File "D:\Python27\lib\site-packages\django\core\urlresolvers.py", line 402, in url_patterns
    patterns = getattr(self.urlconf_module, "urlpatterns", self.urlconf_module)
  File "D:\Python27\lib\site-packages\django\core\urlresolvers.py", line 396, in urlconf_module
    self._urlconf_module = import_module(self.urlconf_name)
  File "D:\Python27\lib\importlib\__init__.py", line 37, in import_module
    __import__(name)
  File "H:\Coding\workstation\BBS_Pro\src\BBS_Pro\urls.py", line 54, in <module>
    url(r'^ckeditor/', include('ckeditor.urls')),
  File "D:\Python27\lib\site-packages\django\conf\urls\__init__.py", line 33, in include
    urlconf_module = import_module(urlconf_module)
  File "D:\Python27\lib\importlib\__init__.py", line 37, in import_module
    __import__(name)
ImportError: No module named urls
2016-06-29 14:42:10,410 [Thread-11:111512] [django.request:256] [ERROR]- Internal Server Error: /
Traceback (most recent call last):
  File "D:\Python27\lib\site-packages\django\core\handlers\base.py", line 119, in get_response
    resolver_match = resolver.resolve(request.path_info)
  File "D:\Python27\lib\site-packages\django\core\urlresolvers.py", line 366, in resolve
    for pattern in self.url_patterns:
  File "D:\Python27\lib\site-packages\django\core\urlresolvers.py", line 402, in url_patterns
    patterns = getattr(self.urlconf_module, "urlpatterns", self.urlconf_module)
  File "D:\Python27\lib\site-packages\django\core\urlresolvers.py", line 396, in urlconf_module
    self._urlconf_module = import_module(self.urlconf_name)
  File "D:\Python27\lib\importlib\__init__.py", line 37, in import_module
    __import__(name)
  File "H:\Coding\workstation\BBS_Pro\src\BBS_Pro\urls.py", line 54, in <module>
    url(r'^ckeditor/', include('ckeditor.urls')),
  File "D:\Python27\lib\site-packages\django\conf\urls\__init__.py", line 33, in include
    urlconf_module = import_module(urlconf_module)
  File "D:\Python27\lib\importlib\__init__.py", line 37, in import_module
    __import__(name)
ImportError: No module named urls
2016-06-29 14:42:11,029 [Thread-12:111516] [django.request:256] [ERROR]- Internal Server Error: /
Traceback (most recent call last):
  File "D:\Python27\lib\site-packages\django\core\handlers\base.py", line 119, in get_response
    resolver_match = resolver.resolve(request.path_info)
  File "D:\Python27\lib\site-packages\django\core\urlresolvers.py", line 366, in resolve
    for pattern in self.url_patterns:
  File "D:\Python27\lib\site-packages\django\core\urlresolvers.py", line 402, in url_patterns
    patterns = getattr(self.urlconf_module, "urlpatterns", self.urlconf_module)
  File "D:\Python27\lib\site-packages\django\core\urlresolvers.py", line 396, in urlconf_module
    self._urlconf_module = import_module(self.urlconf_name)
  File "D:\Python27\lib\importlib\__init__.py", line 37, in import_module
    __import__(name)
  File "H:\Coding\workstation\BBS_Pro\src\BBS_Pro\urls.py", line 54, in <module>
    url(r'^ckeditor/', include('ckeditor.urls')),
  File "D:\Python27\lib\site-packages\django\conf\urls\__init__.py", line 33, in include
    urlconf_module = import_module(urlconf_module)
  File "D:\Python27\lib\importlib\__init__.py", line 37, in import_module
    __import__(name)
ImportError: No module named urls
2016-06-29 14:42:11,230 [Thread-13:111520] [django.request:256] [ERROR]- Internal Server Error: /
Traceback (most recent call last):
  File "D:\Python27\lib\site-packages\django\core\handlers\base.py", line 119, in get_response
    resolver_match = resolver.resolve(request.path_info)
  File "D:\Python27\lib\site-packages\django\core\urlresolvers.py", line 366, in resolve
    for pattern in self.url_patterns:
  File "D:\Python27\lib\site-packages\django\core\urlresolvers.py", line 402, in url_patterns
    patterns = getattr(self.urlconf_module, "urlpatterns", self.urlconf_module)
  File "D:\Python27\lib\site-packages\django\core\urlresolvers.py", line 396, in urlconf_module
    self._urlconf_module = import_module(self.urlconf_name)
  File "D:\Python27\lib\importlib\__init__.py", line 37, in import_module
    __import__(name)
  File "H:\Coding\workstation\BBS_Pro\src\BBS_Pro\urls.py", line 54, in <module>
    url(r'^ckeditor/', include('ckeditor.urls')),
  File "D:\Python27\lib\site-packages\django\conf\urls\__init__.py", line 33, in include
    urlconf_module = import_module(urlconf_module)
  File "D:\Python27\lib\importlib\__init__.py", line 37, in import_module
    __import__(name)
ImportError: No module named urls
2016-06-29 14:42:11,461 [Thread-14:111524] [django.request:256] [ERROR]- Internal Server Error: /
Traceback (most recent call last):
  File "D:\Python27\lib\site-packages\django\core\handlers\base.py", line 119, in get_response
    resolver_match = resolver.resolve(request.path_info)
  File "D:\Python27\lib\site-packages\django\core\urlresolvers.py", line 366, in resolve
    for pattern in self.url_patterns:
  File "D:\Python27\lib\site-packages\django\core\urlresolvers.py", line 402, in url_patterns
    patterns = getattr(self.urlconf_module, "urlpatterns", self.urlconf_module)
  File "D:\Python27\lib\site-packages\django\core\urlresolvers.py", line 396, in urlconf_module
    self._urlconf_module = import_module(self.urlconf_name)
  File "D:\Python27\lib\importlib\__init__.py", line 37, in import_module
    __import__(name)
  File "H:\Coding\workstation\BBS_Pro\src\BBS_Pro\urls.py", line 54, in <module>
    url(r'^ckeditor/', include('ckeditor.urls')),
  File "D:\Python27\lib\site-packages\django\conf\urls\__init__.py", line 33, in include
    urlconf_module = import_module(urlconf_module)
  File "D:\Python27\lib\importlib\__init__.py", line 37, in import_module
    __import__(name)
ImportError: No module named urls
2016-06-29 14:42:11,657 [Thread-15:111528] [django.request:256] [ERROR]- Internal Server Error: /
Traceback (most recent call last):
  File "D:\Python27\lib\site-packages\django\core\handlers\base.py", line 119, in get_response
    resolver_match = resolver.resolve(request.path_info)
  File "D:\Python27\lib\site-packages\django\core\urlresolvers.py", line 366, in resolve
    for pattern in self.url_patterns:
  File "D:\Python27\lib\site-packages\django\core\urlresolvers.py", line 402, in url_patterns
    patterns = getattr(self.urlconf_module, "urlpatterns", self.urlconf_module)
  File "D:\Python27\lib\site-packages\django\core\urlresolvers.py", line 396, in urlconf_module
    self._urlconf_module = import_module(self.urlconf_name)
  File "D:\Python27\lib\importlib\__init__.py", line 37, in import_module
    __import__(name)
  File "H:\Coding\workstation\BBS_Pro\src\BBS_Pro\urls.py", line 54, in <module>
    url(r'^ckeditor/', include('ckeditor.urls')),
  File "D:\Python27\lib\site-packages\django\conf\urls\__init__.py", line 33, in include
    urlconf_module = import_module(urlconf_module)
  File "D:\Python27\lib\importlib\__init__.py", line 37, in import_module
    __import__(name)
ImportError: No module named urls
2016-06-29 14:44:07,694 [Thread-22:111040] [django.request:170] [WARNING]- Not Found: /Jumbotron Template for Bootstrap_files/jumbotron.css
2016-06-29 14:44:10,119 [Thread-42:111132] [django.request:170] [WARNING]- Not Found: /Jumbotron Template for Bootstrap_files/jumbotron.css
2016-06-29 14:50:00,657 [Thread-25:111364] [django.request:170] [WARNING]- Not Found: /statics/admin/js/jquery.min.js
2016-06-29 14:50:00,928 [Thread-28:107972] [django.request:170] [WARNING]- Not Found: /statics/admin/js/jquery.min.js
2016-06-29 14:50:07,676 [Thread-45:110976] [django.request:170] [WARNING]- Not Found: /statics/admin/js/jquery.min.js
2016-06-29 14:50:07,897 [Thread-48:110676] [django.request:170] [WARNING]- Not Found: /statics/admin/js/jquery.min.js
2016-06-29 14:50:30,928 [Thread-61:107976] [django.request:170] [WARNING]- Not Found: /statics/admin/js/jquery.min.js
2016-06-29 14:52:57,632 [Thread-78:110080] [django.request:170] [WARNING]- Not Found: /Jumbotron Template for Bootstrap_files/jumbotron.css
2016-06-29 14:52:58,181 [Thread-80:109844] [django.request:170] [WARNING]- Not Found: /Jumbotron Template for Bootstrap_files/jumbotron.css
2016-06-29 14:53:30,681 [Thread-93:111212] [django.request:170] [WARNING]- Not Found: /statics/admin/js/jquery.min.js
2016-06-29 14:53:31,046 [Thread-96:111008] [django.request:170] [WARNING]- Not Found: /statics/admin/js/jquery.min.js
2016-06-29 15:06:29,908 [Thread-120:111000] [django.request:170] [WARNING]- Not Found: /statics/admin/js/jquery.min.js
2016-06-29 15:06:30,115 [Thread-123:112168] [django.request:170] [WARNING]- Not Found: /statics/admin/js/jquery.min.js
2016-06-29 15:06:46,895 [Thread-12:111680] [django.request:170] [WARNING]- Not Found: /statics/admin/js/jquery.min.js
2016-06-29 15:06:47,131 [Thread-21:112384] [django.request:170] [WARNING]- Not Found: /statics/admin/js/jquery.min.js
2016-06-29 15:16:57,710 [Thread-3:112416] [django.request:256] [ERROR]- Internal Server Error: /bbs/bbsdetail/1/
Traceback (most recent call last):
  File "D:\Python27\lib\site-packages\django\core\handlers\base.py", line 132, in get_response
    response = wrapped_callback(request, *callback_args, **callback_kwargs)
  File "D:\Python27\lib\site-packages\django\contrib\auth\decorators.py", line 22, in _wrapped_view
    return view_func(request, *args, **kwargs)
  File "H:\Coding\workstation\BBS_Pro\src\bbs\views.py", line 106, in bbs_detail
    'user': request.user,}
  File "D:\Python27\lib\site-packages\django\shortcuts.py", line 39, in render_to_response
    content = loader.render_to_string(template_name, context, using=using)
  File "D:\Python27\lib\site-packages\django\template\loader.py", line 98, in render_to_string
    template = get_template(template_name, using=using)
  File "D:\Python27\lib\site-packages\django\template\loader.py", line 35, in get_template
    return engine.get_template(template_name, dirs)
  File "D:\Python27\lib\site-packages\django\template\backends\django.py", line 30, in get_template
    return Template(self.engine.get_template(template_name, dirs))
  File "D:\Python27\lib\site-packages\django\template\engine.py", line 167, in get_template
    template, origin = self.find_template(template_name, dirs)
  File "D:\Python27\lib\site-packages\django\template\engine.py", line 141, in find_template
    source, display_name = loader(name, dirs)
  File "D:\Python27\lib\site-packages\django\template\loaders\base.py", line 13, in __call__
    return self.load_template(template_name, template_dirs)
  File "D:\Python27\lib\site-packages\django\template\loaders\base.py", line 23, in load_template
    template = Template(source, origin, template_name, self.engine)
  File "D:\Python27\lib\site-packages\django\template\base.py", line 190, in __init__
    self.nodelist = engine.compile_string(template_string, origin)
  File "D:\Python27\lib\site-packages\django\template\engine.py", line 261, in compile_string
    return parser.parse()
  File "D:\Python27\lib\site-packages\django\template\base.py", line 341, in parse
    compiled_result = compile_func(self, token)
  File "D:\Python27\lib\site-packages\django\template\loader_tags.py", line 210, in do_extends
    nodelist = parser.parse()
  File "D:\Python27\lib\site-packages\django\template\base.py", line 341, in parse
    compiled_result = compile_func(self, token)
  File "D:\Python27\lib\site-packages\django\template\loader_tags.py", line 184, in do_block
    nodelist = parser.parse(('endblock',))
  File "D:\Python27\lib\site-packages\django\template\base.py", line 339, in parse
    self.invalid_block_tag(token, command, parse_until)
  File "D:\Python27\lib\site-packages\django\template\base.py", line 394, in invalid_block_tag
    (command, get_text_list(["'%s'" % p for p in parse_until])))
TemplateSyntaxError: Invalid block tag: 'static', expected 'endblock'
2016-06-29 15:20:07,276 [Thread-264:113228] [django.request:170] [WARNING]- Not Found: /Jumbotron Template for Bootstrap_files/jumbotron.css
2016-06-29 15:20:07,365 [Thread-265:113232] [django.request:170] [WARNING]- Not Found: /Jumbotron Template for Bootstrap_files/jumbotron.css
2016-06-29 15:21:24,263 [Thread-285:112208] [django.request:170] [WARNING]- Not Found: /Jumbotron Template for Bootstrap_files/jumbotron.css
2016-06-29 15:21:24,734 [Thread-286:113548] [django.request:170] [WARNING]- Not Found: /Jumbotron Template for Bootstrap_files/jumbotron.css
2016-06-29 15:30:34,154 [Thread-354:110664] [django.request:170] [WARNING]- Not Found: /Jumbotron Template for Bootstrap_files/jumbotron.css
2016-06-29 15:30:41,026 [Thread-355:109480] [django.request:170] [WARNING]- Not Found: /Jumbotron Template for Bootstrap_files/jumbotron.css
2016-06-29 15:55:24,108 [Thread-2:114332] [django.request:256] [ERROR]- Internal Server Error: /assets/add
Traceback (most recent call last):
  File "D:\Python27\lib\site-packages\django\core\handlers\base.py", line 108, in get_response
    response = middleware_method(request)
  File "D:\Python27\lib\site-packages\django\middleware\common.py", line 74, in process_request
    if (not urlresolvers.is_valid_path(request.path_info, urlconf) and
  File "D:\Python27\lib\site-packages\django\core\urlresolvers.py", line 647, in is_valid_path
    resolve(path, urlconf)
  File "D:\Python27\lib\site-packages\django\core\urlresolvers.py", line 522, in resolve
    return get_resolver(urlconf).resolve(path)
  File "D:\Python27\lib\site-packages\django\core\urlresolvers.py", line 368, in resolve
    sub_match = pattern.resolve(new_path)
  File "D:\Python27\lib\site-packages\django\core\urlresolvers.py", line 368, in resolve
    sub_match = pattern.resolve(new_path)
  File "D:\Python27\lib\site-packages\django\core\urlresolvers.py", line 240, in resolve
    return ResolverMatch(self.callback, args, kwargs, self.name)
  File "D:\Python27\lib\site-packages\django\core\urlresolvers.py", line 247, in callback
    self._callback = get_callable(self._callback_str)
  File "D:\Python27\lib\site-packages\django\utils\lru_cache.py", line 101, in wrapper
    result = user_function(*args, **kwds)
  File "D:\Python27\lib\site-packages\django\core\urlresolvers.py", line 106, in get_callable
    mod = import_module(mod_name)
  File "D:\Python27\lib\importlib\__init__.py", line 37, in import_module
    __import__(name)
  File "H:\Coding\workstation\BBS_Pro\src\assets\views.py", line 7, in <module>
    from forms import HostForm
  File "H:\Coding\workstation\BBS_Pro\src\assets\forms.py", line 19, in <module>
    class HostForm(ModelForm):
  File "H:\Coding\workstation\BBS_Pro\src\assets\forms.py", line 37, in HostForm
    kv_user = map(lambda mr:(mr[1], mr[1]), user_list)
  File "H:\Coding\workstation\BBS_Pro\src\assets\forms.py", line 37, in <lambda>
    kv_user = map(lambda mr:(mr[1], mr[1]), user_list)
IndexError: tuple index out of range
2016-06-29 16:03:13,085 [Thread-20:115016] [django.request:170] [WARNING]- Not Found: /Jumbotron Template for Bootstrap_files/jumbotron.css
2016-06-29 16:08:05,025 [Thread-144:114660] [django.request:170] [WARNING]- Not Found: /Jumbotron Template for Bootstrap_files/jumbotron.css
2016-06-29 16:08:05,186 [Thread-145:114028] [django.request:170] [WARNING]- Not Found: /Jumbotron Template for Bootstrap_files/jumbotron.css
2016-06-29 16:11:04,539 [Thread-253:115556] [django.request:170] [WARNING]- Not Found: /Jumbotron Template for Bootstrap_files/jumbotron.css
2016-06-29 16:11:04,928 [Thread-255:115192] [django.request:170] [WARNING]- Not Found: /Jumbotron Template for Bootstrap_files/jumbotron.css
2016-06-29 16:55:22,362 [Thread-52:117636] [django.request:170] [WARNING]- Not Found: /Jumbotron Template for Bootstrap_files/jumbotron.css
2016-06-29 16:55:22,509 [Thread-53:115248] [django.request:170] [WARNING]- Not Found: /Jumbotron Template for Bootstrap_files/jumbotron.css
2016-06-29 16:56:12,621 [Thread-154:117424] [django.request:170] [WARNING]- Not Found: /assets/add/
2016-06-29 16:58:48,374 [Thread-167:117600] [django.request:256] [ERROR]- Internal Server Error: /assets/add
Traceback (most recent call last):
  File "D:\Python27\lib\site-packages\django\core\handlers\base.py", line 108, in get_response
    response = middleware_method(request)
  File "D:\Python27\lib\site-packages\django\middleware\common.py", line 84, in process_request
    "settings.") % (new_url[0], new_url[1]))
RuntimeError: You called this URL via POST, but the URL doesn't end in a slash and you have APPEND_SLASH set. Django can't redirect to the slash URL while maintaining POST data. Change your form to point to 127.0.0.1:8000/assets/add/ (note the trailing slash), or set APPEND_SLASH=False in your Django settings.
2016-06-29 17:02:44,509 [Thread-219:117384] [django.request:170] [WARNING]- Not Found: /favicon.ico
2016-06-29 17:03:22,391 [Thread-230:117860] [django.request:256] [ERROR]- Internal Server Error: /assets/add
Traceback (most recent call last):
  File "D:\Python27\lib\site-packages\django\core\handlers\base.py", line 108, in get_response
    response = middleware_method(request)
  File "D:\Python27\lib\site-packages\django\middleware\common.py", line 84, in process_request
    "settings.") % (new_url[0], new_url[1]))
RuntimeError: You called this URL via POST, but the URL doesn't end in a slash and you have APPEND_SLASH set. Django can't redirect to the slash URL while maintaining POST data. Change your form to point to 127.0.0.1:8000/assets/add/ (note the trailing slash), or set APPEND_SLASH=False in your Django settings.
2016-06-29 17:03:47,051 [Thread-272:118140] [django.request:256] [ERROR]- Internal Server Error: /assets/add/
Traceback (most recent call last):
  File "D:\Python27\lib\site-packages\django\core\handlers\base.py", line 132, in get_response
    response = wrapped_callback(request, *callback_args, **callback_kwargs)
  File "D:\Python27\lib\site-packages\django\contrib\auth\decorators.py", line 22, in _wrapped_view
    return view_func(request, *args, **kwargs)
  File "H:\Coding\workstation\BBS_Pro\src\assets\views.py", line 23, in add
    if form.is_valid():
  File "D:\Python27\lib\site-packages\django\forms\forms.py", line 184, in is_valid
    return self.is_bound and not self.errors
  File "D:\Python27\lib\site-packages\django\forms\forms.py", line 176, in errors
    self.full_clean()
  File "D:\Python27\lib\site-packages\django\forms\forms.py", line 394, in full_clean
    self._post_clean()
  File "D:\Python27\lib\site-packages\django\forms\models.py", line 427, in _post_clean
    self.instance = construct_instance(self, self.instance, opts.fields, construct_instance_exclude)
  File "D:\Python27\lib\site-packages\django\forms\models.py", line 62, in construct_instance
    f.save_form_data(instance, cleaned_data[f.name])
  File "D:\Python27\lib\site-packages\django\db\models\fields\__init__.py", line 874, in save_form_data
    setattr(instance, self.name, data)
  File "D:\Python27\lib\site-packages\django\db\models\fields\related.py", line 627, in __set__
    self.field.rel.to._meta.object_name,
ValueError: Cannot assign "u'suqirui'": "Host.supporter" must be a "BBS_user" instance.
2016-06-29 17:03:47,575 [Thread-273:118148] [django.request:170] [WARNING]- Not Found: /favicon.ico
2016-06-29 17:07:35,000 [Thread-285:118736] [django.request:170] [WARNING]- Not Found: /statics/admin/js/jquery.min.js
2016-06-29 17:09:53,808 [Thread-309:117388] [django.request:256] [ERROR]- Internal Server Error: /assets/add/
Traceback (most recent call last):
  File "D:\Python27\lib\site-packages\django\core\handlers\base.py", line 132, in get_response
    response = wrapped_callback(request, *callback_args, **callback_kwargs)
  File "D:\Python27\lib\site-packages\django\contrib\auth\decorators.py", line 22, in _wrapped_view
    return view_func(request, *args, **kwargs)
  File "H:\Coding\workstation\BBS_Pro\src\assets\views.py", line 23, in add
    if form.is_valid():
  File "D:\Python27\lib\site-packages\django\forms\forms.py", line 184, in is_valid
    return self.is_bound and not self.errors
  File "D:\Python27\lib\site-packages\django\forms\forms.py", line 176, in errors
    self.full_clean()
  File "D:\Python27\lib\site-packages\django\forms\forms.py", line 394, in full_clean
    self._post_clean()
  File "D:\Python27\lib\site-packages\django\forms\models.py", line 427, in _post_clean
    self.instance = construct_instance(self, self.instance, opts.fields, construct_instance_exclude)
  File "D:\Python27\lib\site-packages\django\forms\models.py", line 62, in construct_instance
    f.save_form_data(instance, cleaned_data[f.name])
  File "D:\Python27\lib\site-packages\django\db\models\fields\__init__.py", line 874, in save_form_data
    setattr(instance, self.name, data)
  File "D:\Python27\lib\site-packages\django\db\models\fields\related.py", line 627, in __set__
    self.field.rel.to._meta.object_name,
ValueError: Cannot assign "u'devops'": "Host.supporter" must be a "BBS_user" instance.
2016-06-29 17:19:03,691 [Thread-43:117376] [django.request:256] [ERROR]- Internal Server Error: /assets/add/
Traceback (most recent call last):
  File "D:\Python27\lib\site-packages\django\core\handlers\base.py", line 132, in get_response
    response = wrapped_callback(request, *callback_args, **callback_kwargs)
  File "D:\Python27\lib\site-packages\django\contrib\auth\decorators.py", line 22, in _wrapped_view
    return view_func(request, *args, **kwargs)
  File "H:\Coding\workstation\BBS_Pro\src\assets\views.py", line 23, in add
    if form.is_valid():
  File "D:\Python27\lib\site-packages\django\forms\forms.py", line 184, in is_valid
    return self.is_bound and not self.errors
  File "D:\Python27\lib\site-packages\django\forms\forms.py", line 176, in errors
    self.full_clean()
  File "D:\Python27\lib\site-packages\django\forms\forms.py", line 392, in full_clean
    self._clean_fields()
  File "D:\Python27\lib\site-packages\django\forms\forms.py", line 410, in _clean_fields
    value = getattr(self, 'clean_%s' % name)()
  File "H:\Coding\workstation\BBS_Pro\src\assets\forms.py", line 54, in clean_supporter
    return BBS_user.objects.get(user = User.objects.get(username=self.clean_data('supporter')))
AttributeError: 'HostForm' object has no attribute 'clean_data'
2016-06-29 17:19:04,196 [Thread-44:117812] [django.request:170] [WARNING]- Not Found: /favicon.ico
2016-06-29 17:19:29,460 [Thread-2:118692] [django.request:256] [ERROR]- Internal Server Error: /assets/add/
Traceback (most recent call last):
  File "D:\Python27\lib\site-packages\django\core\handlers\base.py", line 132, in get_response
    response = wrapped_callback(request, *callback_args, **callback_kwargs)
  File "D:\Python27\lib\site-packages\django\contrib\auth\decorators.py", line 22, in _wrapped_view
    return view_func(request, *args, **kwargs)
  File "H:\Coding\workstation\BBS_Pro\src\assets\views.py", line 23, in add
    if form.is_valid():
  File "D:\Python27\lib\site-packages\django\forms\forms.py", line 184, in is_valid
    return self.is_bound and not self.errors
  File "D:\Python27\lib\site-packages\django\forms\forms.py", line 176, in errors
    self.full_clean()
  File "D:\Python27\lib\site-packages\django\forms\forms.py", line 392, in full_clean
    self._clean_fields()
  File "D:\Python27\lib\site-packages\django\forms\forms.py", line 410, in _clean_fields
    value = getattr(self, 'clean_%s' % name)()
  File "H:\Coding\workstation\BBS_Pro\src\assets\forms.py", line 54, in clean_supporter
    return BBS_user.objects.get(user = User.objects.get(username=self.cleaned_data('supporter')))
TypeError: 'dict' object is not callable
2016-06-29 17:21:33,253 [Thread-43:118236] [django.request:256] [ERROR]- Internal Server Error: /assets/add/
Traceback (most recent call last):
  File "D:\Python27\lib\site-packages\django\core\handlers\base.py", line 132, in get_response
    response = wrapped_callback(request, *callback_args, **callback_kwargs)
  File "D:\Python27\lib\site-packages\django\contrib\auth\decorators.py", line 22, in _wrapped_view
    return view_func(request, *args, **kwargs)
  File "H:\Coding\workstation\BBS_Pro\src\assets\views.py", line 23, in add
    if form.is_valid():
  File "D:\Python27\lib\site-packages\django\forms\forms.py", line 184, in is_valid
    return self.is_bound and not self.errors
  File "D:\Python27\lib\site-packages\django\forms\forms.py", line 176, in errors
    self.full_clean()
  File "D:\Python27\lib\site-packages\django\forms\forms.py", line 392, in full_clean
    self._clean_fields()
  File "D:\Python27\lib\site-packages\django\forms\forms.py", line 410, in _clean_fields
    value = getattr(self, 'clean_%s' % name)()
  File "H:\Coding\workstation\BBS_Pro\src\assets\forms.py", line 54, in clean_supporter
    user = User.objects.get(username=self.cleaned_data('supporter'))
TypeError: 'dict' object is not callable
2016-06-29 17:21:33,779 [Thread-44:117844] [django.request:170] [WARNING]- Not Found: /favicon.ico
2016-06-29 17:22:27,790 [Thread-43:118652] [django.request:256] [ERROR]- Internal Server Error: /assets/add/
Traceback (most recent call last):
  File "D:\Python27\lib\site-packages\django\core\handlers\base.py", line 132, in get_response
    response = wrapped_callback(request, *callback_args, **callback_kwargs)
  File "D:\Python27\lib\site-packages\django\contrib\auth\decorators.py", line 22, in _wrapped_view
    return view_func(request, *args, **kwargs)
  File "H:\Coding\workstation\BBS_Pro\src\assets\views.py", line 23, in add
    if form.is_valid():
  File "D:\Python27\lib\site-packages\django\forms\forms.py", line 184, in is_valid
    return self.is_bound and not self.errors
  File "D:\Python27\lib\site-packages\django\forms\forms.py", line 176, in errors
    self.full_clean()
  File "D:\Python27\lib\site-packages\django\forms\forms.py", line 394, in full_clean
    self._post_clean()
  File "D:\Python27\lib\site-packages\django\forms\models.py", line 427, in _post_clean
    self.instance = construct_instance(self, self.instance, opts.fields, construct_instance_exclude)
  File "D:\Python27\lib\site-packages\django\forms\models.py", line 62, in construct_instance
    f.save_form_data(instance, cleaned_data[f.name])
  File "D:\Python27\lib\site-packages\django\db\models\fields\__init__.py", line 874, in save_form_data
    setattr(instance, self.name, data)
  File "D:\Python27\lib\site-packages\django\db\models\fields\related.py", line 627, in __set__
    self.field.rel.to._meta.object_name,
ValueError: Cannot assign "u'\u5317\u4eac\u4e16\u7eaa\u4e92\u8054\u673a\u623f'": "Host.mroom" must be a "Machine_Room" instance.
2016-06-29 17:22:29,259 [Thread-44:118376] [django.request:170] [WARNING]- Not Found: /favicon.ico
2016-06-29 17:35:23,869 [Thread-45:118800] [django.request:256] [ERROR]- Internal Server Error: /assets/add
Traceback (most recent call last):
  File "D:\Python27\lib\site-packages\django\core\handlers\base.py", line 108, in get_response
    response = middleware_method(request)
  File "D:\Python27\lib\site-packages\django\middleware\common.py", line 84, in process_request
    "settings.") % (new_url[0], new_url[1]))
RuntimeError: You called this URL via POST, but the URL doesn't end in a slash and you have APPEND_SLASH set. Django can't redirect to the slash URL while maintaining POST data. Change your form to point to 127.0.0.1:8000/assets/add/ (note the trailing slash), or set APPEND_SLASH=False in your Django settings.
2016-06-29 17:35:46,586 [Thread-143:118652] [django.request:256] [ERROR]- Internal Server Error: /assets/add/
Traceback (most recent call last):
  File "D:\Python27\lib\site-packages\django\core\handlers\base.py", line 132, in get_response
    response = wrapped_callback(request, *callback_args, **callback_kwargs)
  File "D:\Python27\lib\site-packages\django\contrib\auth\decorators.py", line 22, in _wrapped_view
    return view_func(request, *args, **kwargs)
  File "H:\Coding\workstation\BBS_Pro\src\assets\views.py", line 23, in add
    if form.is_valid():
  File "D:\Python27\lib\site-packages\django\forms\forms.py", line 184, in is_valid
    return self.is_bound and not self.errors
  File "D:\Python27\lib\site-packages\django\forms\forms.py", line 176, in errors
    self.full_clean()
  File "D:\Python27\lib\site-packages\django\forms\forms.py", line 394, in full_clean
    self._post_clean()
  File "D:\Python27\lib\site-packages\django\forms\models.py", line 427, in _post_clean
    self.instance = construct_instance(self, self.instance, opts.fields, construct_instance_exclude)
  File "D:\Python27\lib\site-packages\django\forms\models.py", line 62, in construct_instance
    f.save_form_data(instance, cleaned_data[f.name])
  File "D:\Python27\lib\site-packages\django\db\models\fields\__init__.py", line 874, in save_form_data
    setattr(instance, self.name, data)
  File "D:\Python27\lib\site-packages\django\db\models\fields\related.py", line 627, in __set__
    self.field.rel.to._meta.object_name,
ValueError: Cannot assign "u'\u5317\u4eac\u4e16\u7eaa\u4e92\u8054\u673a\u623f'": "Host.mroom" must be a "Machine_Room" instance.
2016-06-30 13:08:10,220 [Thread-44:127652] [django.request:170] [WARNING]- Not Found: /Jumbotron Template for Bootstrap_files/jumbotron.css
2016-06-30 13:08:23,286 [Thread-53:127720] [django.request:170] [WARNING]- Not Found: /Jumbotron Template for Bootstrap_files/jumbotron.css
2016-06-30 13:08:35,556 [Thread-57:127784] [django.request:170] [WARNING]- Not Found: /statics/admin/js/jquery.min.js
2016-06-30 13:08:35,992 [Thread-61:127808] [django.request:170] [WARNING]- Not Found: /favicon.ico
2016-06-30 13:28:55,548 [Thread-77:128856] [django.request:170] [WARNING]- Not Found: /Jumbotron Template for Bootstrap_files/jumbotron.css
2016-06-30 13:28:56,144 [Thread-79:126792] [django.request:170] [WARNING]- Not Found: /Jumbotron Template for Bootstrap_files/jumbotron.css
2016-06-30 13:34:38,279 [Thread-105:127664] [django.request:170] [WARNING]- Not Found: /Jumbotron Template for Bootstrap_files/jumbotron.css
2016-06-30 14:13:41,661 [Thread-45:56612] [django.request:170] [WARNING]- Not Found: /Jumbotron Template for Bootstrap_files/jumbotron.css
2016-06-30 14:14:02,279 [Thread-53:124564] [django.request:170] [WARNING]- Not Found: /favicon.ico
2016-06-30 14:47:12,842 [Thread-2:131340] [django.request:256] [ERROR]- Internal Server Error: /bbs/bbsdetail/45/
Traceback (most recent call last):
  File "D:\Python27\lib\site-packages\django\core\handlers\base.py", line 132, in get_response
    response = wrapped_callback(request, *callback_args, **callback_kwargs)
  File "D:\Python27\lib\site-packages\django\contrib\auth\decorators.py", line 22, in _wrapped_view
    return view_func(request, *args, **kwargs)
  File "H:\Coding\workstation\BBS_Pro\src\bbs\views.py", line 106, in bbs_detail
    'user': request.user,}
  File "D:\Python27\lib\site-packages\django\shortcuts.py", line 39, in render_to_response
    content = loader.render_to_string(template_name, context, using=using)
  File "D:\Python27\lib\site-packages\django\template\loader.py", line 99, in render_to_string
    return template.render(context, request)
  File "D:\Python27\lib\site-packages\django\template\backends\django.py", line 74, in render
    return self.template.render(context)
  File "D:\Python27\lib\site-packages\django\template\base.py", line 209, in render
    return self._render(context)
  File "D:\Python27\lib\site-packages\django\template\base.py", line 201, in _render
    return self.nodelist.render(context)
  File "D:\Python27\lib\site-packages\django\template\base.py", line 903, in render
    bit = self.render_node(node, context)
  File "D:\Python27\lib\site-packages\django\template\debug.py", line 79, in render_node
    return node.render(context)
  File "D:\Python27\lib\site-packages\django\template\loader_tags.py", line 135, in render
    return compiled_parent._render(context)
  File "D:\Python27\lib\site-packages\django\template\base.py", line 201, in _render
    return self.nodelist.render(context)
  File "D:\Python27\lib\site-packages\django\template\base.py", line 903, in render
    bit = self.render_node(node, context)
  File "D:\Python27\lib\site-packages\django\template\debug.py", line 79, in render_node
    return node.render(context)
  File "D:\Python27\lib\site-packages\django\template\defaulttags.py", line 493, in render
    url = reverse(view_name, args=args, kwargs=kwargs, current_app=current_app)
  File "D:\Python27\lib\site-packages\django\core\urlresolvers.py", line 579, in reverse
    return force_text(iri_to_uri(resolver._reverse_with_prefix(view, prefix, *args, **kwargs)))
  File "D:\Python27\lib\site-packages\django\core\urlresolvers.py", line 433, in _reverse_with_prefix
    self._populate()
  File "D:\Python27\lib\site-packages\django\core\urlresolvers.py", line 308, in _populate
    for name in pattern.reverse_dict:
  File "D:\Python27\lib\site-packages\django\core\urlresolvers.py", line 338, in reverse_dict
    self._populate()
  File "D:\Python27\lib\site-packages\django\core\urlresolvers.py", line 326, in _populate
    lookups.appendlist(pattern.callback, (bits, p_pattern, pattern.default_args))
  File "D:\Python27\lib\site-packages\django\core\urlresolvers.py", line 247, in callback
    self._callback = get_callable(self._callback_str)
  File "D:\Python27\lib\site-packages\django\utils\lru_cache.py", line 101, in wrapper
    result = user_function(*args, **kwds)
  File "D:\Python27\lib\site-packages\django\core\urlresolvers.py", line 127, in get_callable
    (lookup_view, mod_name))
ViewDoesNotExist: Could not import 'assets.views.search'. View does not exist in module assets.views.
2016-06-30 14:47:13,983 [Thread-3:131344] [django.request:170] [WARNING]- Not Found: /favicon.ico
2016-06-30 14:49:08,483 [Thread-9:131808] [django.request:256] [ERROR]- Internal Server Error: /bbs/bbsdetail/45/
Traceback (most recent call last):
  File "D:\Python27\lib\site-packages\django\core\handlers\base.py", line 132, in get_response
    response = wrapped_callback(request, *callback_args, **callback_kwargs)
  File "D:\Python27\lib\site-packages\django\contrib\auth\decorators.py", line 22, in _wrapped_view
    return view_func(request, *args, **kwargs)
  File "H:\Coding\workstation\BBS_Pro\src\bbs\views.py", line 106, in bbs_detail
    'user': request.user,}
  File "D:\Python27\lib\site-packages\django\shortcuts.py", line 39, in render_to_response
    content = loader.render_to_string(template_name, context, using=using)
  File "D:\Python27\lib\site-packages\django\template\loader.py", line 99, in render_to_string
    return template.render(context, request)
  File "D:\Python27\lib\site-packages\django\template\backends\django.py", line 74, in render
    return self.template.render(context)
  File "D:\Python27\lib\site-packages\django\template\base.py", line 209, in render
    return self._render(context)
  File "D:\Python27\lib\site-packages\django\template\base.py", line 201, in _render
    return self.nodelist.render(context)
  File "D:\Python27\lib\site-packages\django\template\base.py", line 903, in render
    bit = self.render_node(node, context)
  File "D:\Python27\lib\site-packages\django\template\debug.py", line 79, in render_node
    return node.render(context)
  File "D:\Python27\lib\site-packages\django\template\loader_tags.py", line 135, in render
    return compiled_parent._render(context)
  File "D:\Python27\lib\site-packages\django\template\base.py", line 201, in _render
    return self.nodelist.render(context)
  File "D:\Python27\lib\site-packages\django\template\base.py", line 903, in render
    bit = self.render_node(node, context)
  File "D:\Python27\lib\site-packages\django\template\debug.py", line 79, in render_node
    return node.render(context)
  File "D:\Python27\lib\site-packages\django\template\defaulttags.py", line 493, in render
    url = reverse(view_name, args=args, kwargs=kwargs, current_app=current_app)
  File "D:\Python27\lib\site-packages\django\core\urlresolvers.py", line 579, in reverse
    return force_text(iri_to_uri(resolver._reverse_with_prefix(view, prefix, *args, **kwargs)))
  File "D:\Python27\lib\site-packages\django\core\urlresolvers.py", line 433, in _reverse_with_prefix
    self._populate()
  File "D:\Python27\lib\site-packages\django\core\urlresolvers.py", line 308, in _populate
    for name in pattern.reverse_dict:
  File "D:\Python27\lib\site-packages\django\core\urlresolvers.py", line 338, in reverse_dict
    self._populate()
  File "D:\Python27\lib\site-packages\django\core\urlresolvers.py", line 326, in _populate
    lookups.appendlist(pattern.callback, (bits, p_pattern, pattern.default_args))
  File "D:\Python27\lib\site-packages\django\core\urlresolvers.py", line 247, in callback
    self._callback = get_callable(self._callback_str)
  File "D:\Python27\lib\site-packages\django\utils\lru_cache.py", line 101, in wrapper
    result = user_function(*args, **kwds)
  File "D:\Python27\lib\site-packages\django\core\urlresolvers.py", line 127, in get_callable
    (lookup_view, mod_name))
ViewDoesNotExist: Could not import 'assets.views.search'. View does not exist in module assets.views.
2016-06-30 14:49:09,561 [Thread-10:131812] [django.request:170] [WARNING]- Not Found: /favicon.ico
2016-06-30 14:49:59,767 [Thread-44:131172] [django.request:256] [ERROR]- Internal Server Error: /assets/search/
Traceback (most recent call last):
  File "D:\Python27\lib\site-packages\django\core\handlers\base.py", line 132, in get_response
    response = wrapped_callback(request, *callback_args, **callback_kwargs)
  File "D:\Python27\lib\site-packages\django\contrib\auth\decorators.py", line 22, in _wrapped_view
    return view_func(request, *args, **kwargs)
  File "H:\Coding\workstation\BBS_Pro\src\assets\views.py", line 47, in search
    host_msg_lists = Host.objects.filter(Q(ipaddr__icontains = search_q) | Q(hostname__icontains = search_q))
  File "D:\Python27\lib\site-packages\django\db\models\manager.py", line 127, in manager_method
    return getattr(self.get_queryset(), name)(*args, **kwargs)
  File "D:\Python27\lib\site-packages\django\db\models\query.py", line 679, in filter
    return self._filter_or_exclude(False, *args, **kwargs)
  File "D:\Python27\lib\site-packages\django\db\models\query.py", line 697, in _filter_or_exclude
    clone.query.add_q(Q(*args, **kwargs))
  File "D:\Python27\lib\site-packages\django\db\models\sql\query.py", line 1301, in add_q
    clause, require_inner = self._add_q(where_part, self.used_aliases)
  File "D:\Python27\lib\site-packages\django\db\models\sql\query.py", line 1323, in _add_q
    current_negated, allow_joins)
  File "D:\Python27\lib\site-packages\django\db\models\sql\query.py", line 1328, in _add_q
    current_negated=current_negated, connector=connector, allow_joins=allow_joins)
  File "D:\Python27\lib\site-packages\django\db\models\sql\query.py", line 1150, in build_filter
    value, lookups, used_joins = self.prepare_lookup_value(value, lookups, can_reuse, allow_joins)
  File "D:\Python27\lib\site-packages\django\db\models\sql\query.py", line 990, in prepare_lookup_value
    raise ValueError("Cannot use None as a query value")
ValueError: Cannot use None as a query value
2016-06-30 14:50:01,007 [Thread-45:99336] [django.request:170] [WARNING]- Not Found: /favicon.ico
2016-06-30 14:51:58,026 [Thread-2:131424] [django.request:256] [ERROR]- Internal Server Error: /assets/search/
Traceback (most recent call last):
  File "D:\Python27\lib\site-packages\django\core\handlers\base.py", line 132, in get_response
    response = wrapped_callback(request, *callback_args, **callback_kwargs)
  File "D:\Python27\lib\site-packages\django\contrib\auth\decorators.py", line 22, in _wrapped_view
    return view_func(request, *args, **kwargs)
  File "H:\Coding\workstation\BBS_Pro\src\assets\views.py", line 47, in search
    host_msg_lists = Host.objects.filter(Q(ipaddr__icontains = search_q) | Q(hostname__icontains = search_q))
  File "D:\Python27\lib\site-packages\django\db\models\manager.py", line 127, in manager_method
    return getattr(self.get_queryset(), name)(*args, **kwargs)
  File "D:\Python27\lib\site-packages\django\db\models\query.py", line 679, in filter
    return self._filter_or_exclude(False, *args, **kwargs)
  File "D:\Python27\lib\site-packages\django\db\models\query.py", line 697, in _filter_or_exclude
    clone.query.add_q(Q(*args, **kwargs))
  File "D:\Python27\lib\site-packages\django\db\models\sql\query.py", line 1301, in add_q
    clause, require_inner = self._add_q(where_part, self.used_aliases)
  File "D:\Python27\lib\site-packages\django\db\models\sql\query.py", line 1323, in _add_q
    current_negated, allow_joins)
  File "D:\Python27\lib\site-packages\django\db\models\sql\query.py", line 1328, in _add_q
    current_negated=current_negated, connector=connector, allow_joins=allow_joins)
  File "D:\Python27\lib\site-packages\django\db\models\sql\query.py", line 1150, in build_filter
    value, lookups, used_joins = self.prepare_lookup_value(value, lookups, can_reuse, allow_joins)
  File "D:\Python27\lib\site-packages\django\db\models\sql\query.py", line 990, in prepare_lookup_value
    raise ValueError("Cannot use None as a query value")
ValueError: Cannot use None as a query value
2016-06-30 14:51:58,882 [Thread-3:131432] [django.request:170] [WARNING]- Not Found: /favicon.ico
2016-06-30 14:52:08,244 [Thread-46:131692] [django.request:256] [ERROR]- Internal Server Error: /assets/search/
Traceback (most recent call last):
  File "D:\Python27\lib\site-packages\django\core\handlers\base.py", line 132, in get_response
    response = wrapped_callback(request, *callback_args, **callback_kwargs)
  File "D:\Python27\lib\site-packages\django\contrib\auth\decorators.py", line 22, in _wrapped_view
    return view_func(request, *args, **kwargs)
  File "H:\Coding\workstation\BBS_Pro\src\assets\views.py", line 50, in search
    'host_lists': host_msg_lists,
  File "D:\Python27\lib\site-packages\django\shortcuts.py", line 39, in render_to_response
    content = loader.render_to_string(template_name, context, using=using)
  File "D:\Python27\lib\site-packages\django\template\loader.py", line 98, in render_to_string
    template = get_template(template_name, using=using)
  File "D:\Python27\lib\site-packages\django\template\loader.py", line 46, in get_template
    raise TemplateDoesNotExist(template_name)
TemplateDoesNotExist: search_assets_lists.html
2016-06-30 14:52:09,032 [Thread-47:131700] [django.request:170] [WARNING]- Not Found: /favicon.ico
2016-06-30 15:04:48,582 [Thread-59:131496] [django.request:170] [WARNING]- Not Found: /Jumbotron Template for Bootstrap_files/jumbotron.css
2016-06-30 15:12:10,000 [Thread-107:132476] [django.request:170] [WARNING]- Not Found: /Jumbotron Template for Bootstrap_files/jumbotron.css
2016-06-30 16:22:19,892 [Thread-120:135600] [django.request:170] [WARNING]- Not Found: /Jumbotron Template for Bootstrap_files/jumbotron.css
